[2024-10-29T23:29:30.227+0000] {taskinstance.py:1083} INFO - Dependencies all met for <TaskInstance: httpsensor.check_api manual__2024-10-29T23:29:28.352898+00:00 [queued]>
[2024-10-29T23:29:30.242+0000] {taskinstance.py:1083} INFO - Dependencies all met for <TaskInstance: httpsensor.check_api manual__2024-10-29T23:29:28.352898+00:00 [queued]>
[2024-10-29T23:29:30.243+0000] {taskinstance.py:1279} INFO - 
--------------------------------------------------------------------------------
[2024-10-29T23:29:30.243+0000] {taskinstance.py:1280} INFO - Starting attempt 1 of 1
[2024-10-29T23:29:30.243+0000] {taskinstance.py:1281} INFO - 
--------------------------------------------------------------------------------
[2024-10-29T23:29:30.264+0000] {taskinstance.py:1300} INFO - Executing <Task(HttpSensor): check_api> on 2024-10-29 23:29:28.352898+00:00
[2024-10-29T23:29:30.271+0000] {standard_task_runner.py:55} INFO - Started process 965 to run task
[2024-10-29T23:29:30.277+0000] {standard_task_runner.py:82} INFO - Running: ['***', 'tasks', 'run', 'httpsensor', 'check_api', 'manual__2024-10-29T23:29:28.352898+00:00', '--job-id', '99', '--raw', '--subdir', 'DAGS_FOLDER/sensors.py', '--cfg-path', '/tmp/tmp33odxqz5']
[2024-10-29T23:29:30.279+0000] {standard_task_runner.py:83} INFO - Job 99: Subtask check_api
[2024-10-29T23:29:30.367+0000] {task_command.py:388} INFO - Running <TaskInstance: httpsensor.check_api manual__2024-10-29T23:29:28.352898+00:00 [running]> on host 55e2175811f2
[2024-10-29T23:29:30.454+0000] {taskinstance.py:1509} INFO - Exporting the following env vars:
AIRFLOW_CTX_DAG_OWNER=***
AIRFLOW_CTX_DAG_ID=httpsensor
AIRFLOW_CTX_TASK_ID=check_api
AIRFLOW_CTX_EXECUTION_DATE=2024-10-29T23:29:28.352898+00:00
AIRFLOW_CTX_TRY_NUMBER=1
AIRFLOW_CTX_DAG_RUN_ID=manual__2024-10-29T23:29:28.352898+00:00
[2024-10-29T23:29:30.455+0000] {http.py:122} INFO - Poking: entries
[2024-10-29T23:29:30.468+0000] {base.py:73} INFO - Using connection ID 'connection' for task execution.
[2024-10-29T23:29:30.478+0000] {http.py:208} WARNING - HTTPSConnectionPool(host='api.puplicapis.org', port=443): Max retries exceeded with url: /entries (Caused by NewConnectionError('<urllib3.connection.HTTPSConnection object at 0x763386e94c90>: Failed to establish a new connection: [Errno -2] Name or service not known')) Tenacity will retry to execute the operation
[2024-10-29T23:29:30.479+0000] {taskinstance.py:1768} ERROR - Task failed with exception
Traceback (most recent call last):
  File "/home/airflow/.local/lib/python3.7/site-packages/urllib3/connection.py", line 175, in _new_conn
    (self._dns_host, self.port), self.timeout, **extra_kw
  File "/home/airflow/.local/lib/python3.7/site-packages/urllib3/util/connection.py", line 72, in create_connection
    for res in socket.getaddrinfo(host, port, family, socket.SOCK_STREAM):
  File "/usr/local/lib/python3.7/socket.py", line 752, in getaddrinfo
    for res in _socket.getaddrinfo(host, port, family, type, proto, flags):
socket.gaierror: [Errno -2] Name or service not known

During handling of the above exception, another exception occurred:

Traceback (most recent call last):
  File "/home/airflow/.local/lib/python3.7/site-packages/urllib3/connectionpool.py", line 710, in urlopen
    chunked=chunked,
  File "/home/airflow/.local/lib/python3.7/site-packages/urllib3/connectionpool.py", line 386, in _make_request
    self._validate_conn(conn)
  File "/home/airflow/.local/lib/python3.7/site-packages/urllib3/connectionpool.py", line 1042, in _validate_conn
    conn.connect()
  File "/home/airflow/.local/lib/python3.7/site-packages/urllib3/connection.py", line 358, in connect
    self.sock = conn = self._new_conn()
  File "/home/airflow/.local/lib/python3.7/site-packages/urllib3/connection.py", line 187, in _new_conn
    self, "Failed to establish a new connection: %s" % e
urllib3.exceptions.NewConnectionError: <urllib3.connection.HTTPSConnection object at 0x763386e94c90>: Failed to establish a new connection: [Errno -2] Name or service not known

During handling of the above exception, another exception occurred:

Traceback (most recent call last):
  File "/home/airflow/.local/lib/python3.7/site-packages/requests/adapters.py", line 499, in send
    timeout=timeout,
  File "/home/airflow/.local/lib/python3.7/site-packages/urllib3/connectionpool.py", line 788, in urlopen
    method, url, error=e, _pool=self, _stacktrace=sys.exc_info()[2]
  File "/home/airflow/.local/lib/python3.7/site-packages/urllib3/util/retry.py", line 592, in increment
    raise MaxRetryError(_pool, url, error or ResponseError(cause))
urllib3.exceptions.MaxRetryError: HTTPSConnectionPool(host='api.puplicapis.org', port=443): Max retries exceeded with url: /entries (Caused by NewConnectionError('<urllib3.connection.HTTPSConnection object at 0x763386e94c90>: Failed to establish a new connection: [Errno -2] Name or service not known'))

During handling of the above exception, another exception occurred:

Traceback (most recent call last):
  File "/home/airflow/.local/lib/python3.7/site-packages/airflow/sensors/base.py", line 199, in execute
    poke_return = self.poke(context)
  File "/home/airflow/.local/lib/python3.7/site-packages/airflow/providers/http/sensors/http.py", line 128, in poke
    extra_options=self.extra_options,
  File "/home/airflow/.local/lib/python3.7/site-packages/airflow/providers/http/hooks/http.py", line 151, in run
    return self.run_and_check(session, prepped_request, extra_options)
  File "/home/airflow/.local/lib/python3.7/site-packages/airflow/providers/http/hooks/http.py", line 209, in run_and_check
    raise ex
  File "/home/airflow/.local/lib/python3.7/site-packages/airflow/providers/http/hooks/http.py", line 201, in run_and_check
    response = session.send(prepped_request, **send_kwargs)
  File "/home/airflow/.local/lib/python3.7/site-packages/requests/sessions.py", line 701, in send
    r = adapter.send(request, **kwargs)
  File "/home/airflow/.local/lib/python3.7/site-packages/requests/adapters.py", line 565, in send
    raise ConnectionError(e, request=request)
requests.exceptions.ConnectionError: HTTPSConnectionPool(host='api.puplicapis.org', port=443): Max retries exceeded with url: /entries (Caused by NewConnectionError('<urllib3.connection.HTTPSConnection object at 0x763386e94c90>: Failed to establish a new connection: [Errno -2] Name or service not known'))
[2024-10-29T23:29:30.494+0000] {taskinstance.py:1323} INFO - Marking task as FAILED. dag_id=httpsensor, task_id=check_api, execution_date=20241029T232928, start_date=20241029T232930, end_date=20241029T232930
[2024-10-29T23:29:30.509+0000] {standard_task_runner.py:105} ERROR - Failed to execute job 99 for task check_api (HTTPSConnectionPool(host='api.puplicapis.org', port=443): Max retries exceeded with url: /entries (Caused by NewConnectionError('<urllib3.connection.HTTPSConnection object at 0x763386e94c90>: Failed to establish a new connection: [Errno -2] Name or service not known')); 965)
[2024-10-29T23:29:30.528+0000] {local_task_job.py:208} INFO - Task exited with return code 1
[2024-10-29T23:29:30.565+0000] {taskinstance.py:2578} INFO - 0 downstream tasks scheduled from follow-on schedule check
