[2024-10-29T23:10:47.348+0000] {taskinstance.py:1083} INFO - Dependencies all met for <TaskInstance: windturbine.get_data manual__2024-10-29T23:10:34.034238+00:00 [queued]>
[2024-10-29T23:10:47.372+0000] {taskinstance.py:1083} INFO - Dependencies all met for <TaskInstance: windturbine.get_data manual__2024-10-29T23:10:34.034238+00:00 [queued]>
[2024-10-29T23:10:47.372+0000] {taskinstance.py:1279} INFO - 
--------------------------------------------------------------------------------
[2024-10-29T23:10:47.373+0000] {taskinstance.py:1280} INFO - Starting attempt 2 of 2
[2024-10-29T23:10:47.373+0000] {taskinstance.py:1281} INFO - 
--------------------------------------------------------------------------------
[2024-10-29T23:10:47.396+0000] {taskinstance.py:1300} INFO - Executing <Task(PythonOperator): get_data> on 2024-10-29 23:10:34.034238+00:00
[2024-10-29T23:10:47.405+0000] {standard_task_runner.py:55} INFO - Started process 1138 to run task
[2024-10-29T23:10:47.411+0000] {standard_task_runner.py:82} INFO - Running: ['***', 'tasks', 'run', 'windturbine', 'get_data', 'manual__2024-10-29T23:10:34.034238+00:00', '--job-id', '82', '--raw', '--subdir', 'DAGS_FOLDER/windturbine.py', '--cfg-path', '/tmp/tmp_0wla55a']
[2024-10-29T23:10:47.412+0000] {standard_task_runner.py:83} INFO - Job 82: Subtask get_data
[2024-10-29T23:10:47.510+0000] {task_command.py:388} INFO - Running <TaskInstance: windturbine.get_data manual__2024-10-29T23:10:34.034238+00:00 [running]> on host 55e2175811f2
[2024-10-29T23:10:47.618+0000] {taskinstance.py:1509} INFO - Exporting the following env vars:
AIRFLOW_CTX_DAG_EMAIL=aws@evoluth.com.br
AIRFLOW_CTX_DAG_OWNER=***
AIRFLOW_CTX_DAG_ID=windturbine
AIRFLOW_CTX_TASK_ID=get_data
AIRFLOW_CTX_EXECUTION_DATE=2024-10-29T23:10:34.034238+00:00
AIRFLOW_CTX_TRY_NUMBER=2
AIRFLOW_CTX_DAG_RUN_ID=manual__2024-10-29T23:10:34.034238+00:00
[2024-10-29T23:10:47.706+0000] {taskinstance.py:1768} ERROR - Task failed with exception
Traceback (most recent call last):
  File "/home/airflow/.local/lib/python3.7/site-packages/airflow/operators/python.py", line 175, in execute
    return_value = self.execute_callable()
  File "/home/airflow/.local/lib/python3.7/site-packages/airflow/operators/python.py", line 192, in execute_callable
    return self.python_callable(*self.op_args, **self.op_kwargs)
  File "/opt/airflow/dags/windturbine.py", line 47, in process_file
    os.remove(Variable.get('path_file'))
PermissionError: [Errno 13] Permission denied: '/opt/airflow/data/data.json'
[2024-10-29T23:10:47.716+0000] {taskinstance.py:1323} INFO - Marking task as FAILED. dag_id=windturbine, task_id=get_data, execution_date=20241029T231034, start_date=20241029T231047, end_date=20241029T231047
[2024-10-29T23:10:47.734+0000] {warnings.py:110} WARNING - /home/***/.local/lib/python3.7/site-packages/***/utils/email.py:152: RemovedInAirflow3Warning: Fetching SMTP credentials from configuration variables will be deprecated in a future release. Please set credentials using a connection instead.
  send_mime_email(e_from=mail_from, e_to=recipients, mime_msg=msg, conn_id=conn_id, dryrun=dryrun)

[2024-10-29T23:10:47.735+0000] {configuration.py:663} WARNING - section/key [smtp/smtp_user] not found in config
[2024-10-29T23:10:47.735+0000] {email.py:268} INFO - Email alerting: attempt 1
[2024-10-29T23:10:47.743+0000] {configuration.py:663} WARNING - section/key [smtp/smtp_user] not found in config
[2024-10-29T23:10:47.744+0000] {email.py:268} INFO - Email alerting: attempt 1
[2024-10-29T23:10:47.744+0000] {taskinstance.py:1831} ERROR - Failed to send email to: ['aws@evoluth.com.br']
Traceback (most recent call last):
  File "/home/airflow/.local/lib/python3.7/site-packages/airflow/models/taskinstance.py", line 1374, in _run_raw_task
    self._execute_task_with_callbacks(context, test_mode)
  File "/home/airflow/.local/lib/python3.7/site-packages/airflow/models/taskinstance.py", line 1520, in _execute_task_with_callbacks
    result = self._execute_task(context, task_orig)
  File "/home/airflow/.local/lib/python3.7/site-packages/airflow/models/taskinstance.py", line 1581, in _execute_task
    result = execute_callable(context=context)
  File "/home/airflow/.local/lib/python3.7/site-packages/airflow/operators/python.py", line 175, in execute
    return_value = self.execute_callable()
  File "/home/airflow/.local/lib/python3.7/site-packages/airflow/operators/python.py", line 192, in execute_callable
    return self.python_callable(*self.op_args, **self.op_kwargs)
  File "/opt/airflow/dags/windturbine.py", line 47, in process_file
    os.remove(Variable.get('path_file'))
PermissionError: [Errno 13] Permission denied: '/opt/airflow/data/data.json'

During handling of the above exception, another exception occurred:

Traceback (most recent call last):
  File "/home/airflow/.local/lib/python3.7/site-packages/airflow/models/taskinstance.py", line 2231, in email_alert
    send_email(task.email, subject, html_content)
  File "/home/airflow/.local/lib/python3.7/site-packages/airflow/utils/email.py", line 91, in send_email
    **kwargs,
  File "/home/airflow/.local/lib/python3.7/site-packages/airflow/utils/email.py", line 152, in send_email_smtp
    send_mime_email(e_from=mail_from, e_to=recipients, mime_msg=msg, conn_id=conn_id, dryrun=dryrun)
  File "/home/airflow/.local/lib/python3.7/site-packages/airflow/utils/email.py", line 270, in send_mime_email
    smtp_conn = _get_smtp_connection(smtp_host, smtp_port, smtp_timeout, smtp_ssl)
  File "/home/airflow/.local/lib/python3.7/site-packages/airflow/utils/email.py", line 317, in _get_smtp_connection
    else smtplib.SMTP(host=host, port=port, timeout=timeout)
  File "/usr/local/lib/python3.7/smtplib.py", line 251, in __init__
    (code, msg) = self.connect(host, port)
  File "/usr/local/lib/python3.7/smtplib.py", line 336, in connect
    self.sock = self._get_socket(host, port, self.timeout)
  File "/usr/local/lib/python3.7/smtplib.py", line 307, in _get_socket
    self.source_address)
  File "/usr/local/lib/python3.7/socket.py", line 728, in create_connection
    raise err
  File "/usr/local/lib/python3.7/socket.py", line 716, in create_connection
    sock.connect(sa)
OSError: [Errno 99] Cannot assign requested address

During handling of the above exception, another exception occurred:

Traceback (most recent call last):
  File "/home/airflow/.local/lib/python3.7/site-packages/airflow/models/taskinstance.py", line 1829, in handle_failure
    self.email_alert(error, task)
  File "/home/airflow/.local/lib/python3.7/site-packages/airflow/models/taskinstance.py", line 2233, in email_alert
    send_email(task.email, subject, html_content_err)
  File "/home/airflow/.local/lib/python3.7/site-packages/airflow/utils/email.py", line 91, in send_email
    **kwargs,
  File "/home/airflow/.local/lib/python3.7/site-packages/airflow/utils/email.py", line 152, in send_email_smtp
    send_mime_email(e_from=mail_from, e_to=recipients, mime_msg=msg, conn_id=conn_id, dryrun=dryrun)
  File "/home/airflow/.local/lib/python3.7/site-packages/airflow/utils/email.py", line 270, in send_mime_email
    smtp_conn = _get_smtp_connection(smtp_host, smtp_port, smtp_timeout, smtp_ssl)
  File "/home/airflow/.local/lib/python3.7/site-packages/airflow/utils/email.py", line 317, in _get_smtp_connection
    else smtplib.SMTP(host=host, port=port, timeout=timeout)
  File "/usr/local/lib/python3.7/smtplib.py", line 251, in __init__
    (code, msg) = self.connect(host, port)
  File "/usr/local/lib/python3.7/smtplib.py", line 336, in connect
    self.sock = self._get_socket(host, port, self.timeout)
  File "/usr/local/lib/python3.7/smtplib.py", line 307, in _get_socket
    self.source_address)
  File "/usr/local/lib/python3.7/socket.py", line 728, in create_connection
    raise err
  File "/usr/local/lib/python3.7/socket.py", line 716, in create_connection
    sock.connect(sa)
OSError: [Errno 99] Cannot assign requested address
[2024-10-29T23:10:47.763+0000] {standard_task_runner.py:105} ERROR - Failed to execute job 82 for task get_data ([Errno 13] Permission denied: '/opt/airflow/data/data.json'; 1138)
[2024-10-29T23:10:47.783+0000] {local_task_job.py:208} INFO - Task exited with return code 1
[2024-10-29T23:10:47.821+0000] {taskinstance.py:2578} INFO - 0 downstream tasks scheduled from follow-on schedule check
