[2024-10-30T00:23:15.775+0000] {taskinstance.py:1083} INFO - Dependencies all met for <TaskInstance: consumer.t1 manual__2024-10-30T00:23:14.141123+00:00 [queued]>
[2024-10-30T00:23:15.794+0000] {taskinstance.py:1083} INFO - Dependencies all met for <TaskInstance: consumer.t1 manual__2024-10-30T00:23:14.141123+00:00 [queued]>
[2024-10-30T00:23:15.794+0000] {taskinstance.py:1279} INFO - 
--------------------------------------------------------------------------------
[2024-10-30T00:23:15.794+0000] {taskinstance.py:1280} INFO - Starting attempt 1 of 1
[2024-10-30T00:23:15.794+0000] {taskinstance.py:1281} INFO - 
--------------------------------------------------------------------------------
[2024-10-30T00:23:15.818+0000] {taskinstance.py:1300} INFO - Executing <Task(PythonOperator): t1> on 2024-10-30 00:23:14.141123+00:00
[2024-10-30T00:23:15.836+0000] {standard_task_runner.py:55} INFO - Started process 6791 to run task
[2024-10-30T00:23:15.842+0000] {standard_task_runner.py:82} INFO - Running: ['***', 'tasks', 'run', 'consumer', 't1', 'manual__2024-10-30T00:23:14.141123+00:00', '--job-id', '138', '--raw', '--subdir', 'DAGS_FOLDER/consumer.py', '--cfg-path', '/tmp/tmp25q0k5q4']
[2024-10-30T00:23:15.845+0000] {standard_task_runner.py:83} INFO - Job 138: Subtask t1
[2024-10-30T00:23:15.936+0000] {task_command.py:388} INFO - Running <TaskInstance: consumer.t1 manual__2024-10-30T00:23:14.141123+00:00 [running]> on host 55e2175811f2
[2024-10-30T00:23:16.036+0000] {taskinstance.py:1509} INFO - Exporting the following env vars:
AIRFLOW_CTX_DAG_OWNER=***
AIRFLOW_CTX_DAG_ID=consumer
AIRFLOW_CTX_TASK_ID=t1
AIRFLOW_CTX_EXECUTION_DATE=2024-10-30T00:23:14.141123+00:00
AIRFLOW_CTX_TRY_NUMBER=1
AIRFLOW_CTX_DAG_RUN_ID=manual__2024-10-30T00:23:14.141123+00:00
[2024-10-30T00:23:16.038+0000] {taskinstance.py:1768} ERROR - Task failed with exception
Traceback (most recent call last):
  File "/home/airflow/.local/lib/python3.7/site-packages/airflow/operators/python.py", line 175, in execute
    return_value = self.execute_callable()
  File "/home/airflow/.local/lib/python3.7/site-packages/airflow/operators/python.py", line 192, in execute_callable
    return self.python_callable(*self.op_args, **self.op_kwargs)
  File "/opt/airflow/dags/consumer.py", line 15, in my_file
    dataset = pd.read_csv("/opt/airflow/data/Churn_new.csv", sep=";")
  File "/home/airflow/.local/lib/python3.7/site-packages/pandas/util/_decorators.py", line 311, in wrapper
    return func(*args, **kwargs)
  File "/home/airflow/.local/lib/python3.7/site-packages/pandas/io/parsers/readers.py", line 586, in read_csv
    return _read(filepath_or_buffer, kwds)
  File "/home/airflow/.local/lib/python3.7/site-packages/pandas/io/parsers/readers.py", line 482, in _read
    parser = TextFileReader(filepath_or_buffer, **kwds)
  File "/home/airflow/.local/lib/python3.7/site-packages/pandas/io/parsers/readers.py", line 811, in __init__
    self._engine = self._make_engine(self.engine)
  File "/home/airflow/.local/lib/python3.7/site-packages/pandas/io/parsers/readers.py", line 1040, in _make_engine
    return mapping[engine](self.f, **self.options)  # type: ignore[call-arg]
  File "/home/airflow/.local/lib/python3.7/site-packages/pandas/io/parsers/c_parser_wrapper.py", line 51, in __init__
    self._open_handles(src, kwds)
  File "/home/airflow/.local/lib/python3.7/site-packages/pandas/io/parsers/base_parser.py", line 229, in _open_handles
    errors=kwds.get("encoding_errors", "strict"),
  File "/home/airflow/.local/lib/python3.7/site-packages/pandas/io/common.py", line 707, in get_handle
    newline="",
FileNotFoundError: [Errno 2] No such file or directory: '/opt/airflow/data/Churn_new.csv'
[2024-10-30T00:23:16.050+0000] {taskinstance.py:1323} INFO - Marking task as FAILED. dag_id=consumer, task_id=t1, execution_date=20241030T002314, start_date=20241030T002315, end_date=20241030T002316
[2024-10-30T00:23:16.065+0000] {standard_task_runner.py:105} ERROR - Failed to execute job 138 for task t1 ([Errno 2] No such file or directory: '/opt/airflow/data/Churn_new.csv'; 6791)
[2024-10-30T00:23:16.094+0000] {local_task_job.py:208} INFO - Task exited with return code 1
[2024-10-30T00:23:16.123+0000] {taskinstance.py:2578} INFO - 0 downstream tasks scheduled from follow-on schedule check
