[2024-10-30T00:23:49.645+0000] {taskinstance.py:1083} INFO - Dependencies all met for <TaskInstance: producer.t1 manual__2024-10-30T00:23:48.542744+00:00 [queued]>
[2024-10-30T00:23:49.658+0000] {taskinstance.py:1083} INFO - Dependencies all met for <TaskInstance: producer.t1 manual__2024-10-30T00:23:48.542744+00:00 [queued]>
[2024-10-30T00:23:49.658+0000] {taskinstance.py:1279} INFO - 
--------------------------------------------------------------------------------
[2024-10-30T00:23:49.658+0000] {taskinstance.py:1280} INFO - Starting attempt 1 of 1
[2024-10-30T00:23:49.659+0000] {taskinstance.py:1281} INFO - 
--------------------------------------------------------------------------------
[2024-10-30T00:23:49.677+0000] {taskinstance.py:1300} INFO - Executing <Task(PythonOperator): t1> on 2024-10-30 00:23:48.542744+00:00
[2024-10-30T00:23:49.683+0000] {standard_task_runner.py:55} INFO - Started process 6857 to run task
[2024-10-30T00:23:49.688+0000] {standard_task_runner.py:82} INFO - Running: ['***', 'tasks', 'run', 'producer', 't1', 'manual__2024-10-30T00:23:48.542744+00:00', '--job-id', '140', '--raw', '--subdir', 'DAGS_FOLDER/producer.py', '--cfg-path', '/tmp/tmpqfffjex3']
[2024-10-30T00:23:49.690+0000] {standard_task_runner.py:83} INFO - Job 140: Subtask t1
[2024-10-30T00:23:49.757+0000] {task_command.py:388} INFO - Running <TaskInstance: producer.t1 manual__2024-10-30T00:23:48.542744+00:00 [running]> on host 55e2175811f2
[2024-10-30T00:23:49.835+0000] {taskinstance.py:1509} INFO - Exporting the following env vars:
AIRFLOW_CTX_DAG_OWNER=***
AIRFLOW_CTX_DAG_ID=producer
AIRFLOW_CTX_TASK_ID=t1
AIRFLOW_CTX_EXECUTION_DATE=2024-10-30T00:23:48.542744+00:00
AIRFLOW_CTX_TRY_NUMBER=1
AIRFLOW_CTX_DAG_RUN_ID=manual__2024-10-30T00:23:48.542744+00:00
[2024-10-30T00:23:49.844+0000] {taskinstance.py:1768} ERROR - Task failed with exception
Traceback (most recent call last):
  File "/home/airflow/.local/lib/python3.7/site-packages/airflow/operators/python.py", line 175, in execute
    return_value = self.execute_callable()
  File "/home/airflow/.local/lib/python3.7/site-packages/airflow/operators/python.py", line 192, in execute_callable
    return self.python_callable(*self.op_args, **self.op_kwargs)
  File "/opt/airflow/dags/producer.py", line 17, in my_file
    dataset.to_csv("/opt/airflow/data/Churn_new.csv", sep=";")
  File "/home/airflow/.local/lib/python3.7/site-packages/pandas/core/generic.py", line 3482, in to_csv
    storage_options=storage_options,
  File "/home/airflow/.local/lib/python3.7/site-packages/pandas/io/formats/format.py", line 1105, in to_csv
    csv_formatter.save()
  File "/home/airflow/.local/lib/python3.7/site-packages/pandas/io/formats/csvs.py", line 243, in save
    storage_options=self.storage_options,
  File "/home/airflow/.local/lib/python3.7/site-packages/pandas/io/common.py", line 707, in get_handle
    newline="",
PermissionError: [Errno 13] Permission denied: '/opt/airflow/data/Churn_new.csv'
[2024-10-30T00:23:49.857+0000] {taskinstance.py:1323} INFO - Marking task as FAILED. dag_id=producer, task_id=t1, execution_date=20241030T002348, start_date=20241030T002349, end_date=20241030T002349
[2024-10-30T00:23:49.876+0000] {standard_task_runner.py:105} ERROR - Failed to execute job 140 for task t1 ([Errno 13] Permission denied: '/opt/airflow/data/Churn_new.csv'; 6857)
[2024-10-30T00:23:49.899+0000] {local_task_job.py:208} INFO - Task exited with return code 1
[2024-10-30T00:23:49.922+0000] {taskinstance.py:2578} INFO - 0 downstream tasks scheduled from follow-on schedule check
