[2024-10-29T23:09:58.397+0000] {taskinstance.py:1083} INFO - Dependencies all met for <TaskInstance: producer.t1 manual__2024-10-29T23:09:56.675233+00:00 [queued]>
[2024-10-29T23:09:58.415+0000] {taskinstance.py:1083} INFO - Dependencies all met for <TaskInstance: producer.t1 manual__2024-10-29T23:09:56.675233+00:00 [queued]>
[2024-10-29T23:09:58.415+0000] {taskinstance.py:1279} INFO - 
--------------------------------------------------------------------------------
[2024-10-29T23:09:58.415+0000] {taskinstance.py:1280} INFO - Starting attempt 1 of 1
[2024-10-29T23:09:58.415+0000] {taskinstance.py:1281} INFO - 
--------------------------------------------------------------------------------
[2024-10-29T23:09:58.439+0000] {taskinstance.py:1300} INFO - Executing <Task(PythonOperator): t1> on 2024-10-29 23:09:56.675233+00:00
[2024-10-29T23:09:58.446+0000] {standard_task_runner.py:55} INFO - Started process 1034 to run task
[2024-10-29T23:09:58.449+0000] {standard_task_runner.py:82} INFO - Running: ['***', 'tasks', 'run', 'producer', 't1', 'manual__2024-10-29T23:09:56.675233+00:00', '--job-id', '72', '--raw', '--subdir', 'DAGS_FOLDER/producer.py', '--cfg-path', '/tmp/tmpmjaikfm2']
[2024-10-29T23:09:58.451+0000] {standard_task_runner.py:83} INFO - Job 72: Subtask t1
[2024-10-29T23:09:58.532+0000] {task_command.py:388} INFO - Running <TaskInstance: producer.t1 manual__2024-10-29T23:09:56.675233+00:00 [running]> on host 55e2175811f2
[2024-10-29T23:09:58.618+0000] {taskinstance.py:1509} INFO - Exporting the following env vars:
AIRFLOW_CTX_DAG_OWNER=***
AIRFLOW_CTX_DAG_ID=producer
AIRFLOW_CTX_TASK_ID=t1
AIRFLOW_CTX_EXECUTION_DATE=2024-10-29T23:09:56.675233+00:00
AIRFLOW_CTX_TRY_NUMBER=1
AIRFLOW_CTX_DAG_RUN_ID=manual__2024-10-29T23:09:56.675233+00:00
[2024-10-29T23:09:58.626+0000] {taskinstance.py:1768} ERROR - Task failed with exception
Traceback (most recent call last):
  File "/home/airflow/.local/lib/python3.7/site-packages/airflow/operators/python.py", line 175, in execute
    return_value = self.execute_callable()
  File "/home/airflow/.local/lib/python3.7/site-packages/airflow/operators/python.py", line 192, in execute_callable
    return self.python_callable(*self.op_args, **self.op_kwargs)
  File "/opt/airflow/dags/producer.py", line 17, in my_file
    dataset.to_csv("/opt/airflow/data/Churn_new.csv", sep=";")
  File "/home/airflow/.local/lib/python3.7/site-packages/pandas/core/generic.py", line 3482, in to_csv
    storage_options=storage_options,
  File "/home/airflow/.local/lib/python3.7/site-packages/pandas/io/formats/format.py", line 1105, in to_csv
    csv_formatter.save()
  File "/home/airflow/.local/lib/python3.7/site-packages/pandas/io/formats/csvs.py", line 243, in save
    storage_options=self.storage_options,
  File "/home/airflow/.local/lib/python3.7/site-packages/pandas/io/common.py", line 707, in get_handle
    newline="",
PermissionError: [Errno 13] Permission denied: '/opt/airflow/data/Churn_new.csv'
[2024-10-29T23:09:58.637+0000] {taskinstance.py:1323} INFO - Marking task as FAILED. dag_id=producer, task_id=t1, execution_date=20241029T230956, start_date=20241029T230958, end_date=20241029T230958
[2024-10-29T23:09:58.651+0000] {standard_task_runner.py:105} ERROR - Failed to execute job 72 for task t1 ([Errno 13] Permission denied: '/opt/airflow/data/Churn_new.csv'; 1034)
[2024-10-29T23:09:58.661+0000] {local_task_job.py:208} INFO - Task exited with return code 1
[2024-10-29T23:09:58.684+0000] {taskinstance.py:2578} INFO - 0 downstream tasks scheduled from follow-on schedule check
