[2024-10-30T00:23:16.812+0000] {taskinstance.py:1083} INFO - Dependencies all met for <TaskInstance: bigdata.big_data manual__2024-10-30T00:23:15.616635+00:00 [queued]>
[2024-10-30T00:23:16.828+0000] {taskinstance.py:1083} INFO - Dependencies all met for <TaskInstance: bigdata.big_data manual__2024-10-30T00:23:15.616635+00:00 [queued]>
[2024-10-30T00:23:16.828+0000] {taskinstance.py:1279} INFO - 
--------------------------------------------------------------------------------
[2024-10-30T00:23:16.828+0000] {taskinstance.py:1280} INFO - Starting attempt 1 of 1
[2024-10-30T00:23:16.828+0000] {taskinstance.py:1281} INFO - 
--------------------------------------------------------------------------------
[2024-10-30T00:23:16.845+0000] {taskinstance.py:1300} INFO - Executing <Task(BigDataOperator): big_data> on 2024-10-30 00:23:15.616635+00:00
[2024-10-30T00:23:16.855+0000] {standard_task_runner.py:55} INFO - Started process 6794 to run task
[2024-10-30T00:23:16.858+0000] {standard_task_runner.py:82} INFO - Running: ['***', 'tasks', 'run', 'bigdata', 'big_data', 'manual__2024-10-30T00:23:15.616635+00:00', '--job-id', '139', '--raw', '--subdir', 'DAGS_FOLDER/bigdata.py', '--cfg-path', '/tmp/tmpn3tva01k']
[2024-10-30T00:23:16.859+0000] {standard_task_runner.py:83} INFO - Job 139: Subtask big_data
[2024-10-30T00:23:16.924+0000] {task_command.py:388} INFO - Running <TaskInstance: bigdata.big_data manual__2024-10-30T00:23:15.616635+00:00 [running]> on host 55e2175811f2
[2024-10-30T00:23:17.009+0000] {taskinstance.py:1509} INFO - Exporting the following env vars:
AIRFLOW_CTX_DAG_OWNER=***
AIRFLOW_CTX_DAG_ID=bigdata
AIRFLOW_CTX_TASK_ID=big_data
AIRFLOW_CTX_EXECUTION_DATE=2024-10-30T00:23:15.616635+00:00
AIRFLOW_CTX_TRY_NUMBER=1
AIRFLOW_CTX_DAG_RUN_ID=manual__2024-10-30T00:23:15.616635+00:00
[2024-10-30T00:23:17.020+0000] {taskinstance.py:1768} ERROR - Task failed with exception
Traceback (most recent call last):
  File "/opt/airflow/plugins/big_data_operator.py", line 22, in execute
    df.to_json(self.path_to_save_file)
  File "/home/airflow/.local/lib/python3.7/site-packages/pandas/core/generic.py", line 2571, in to_json
    storage_options=storage_options,
  File "/home/airflow/.local/lib/python3.7/site-packages/pandas/io/json/_json.py", line 131, in to_json
    path_or_buf, "w", compression=compression, storage_options=storage_options
  File "/home/airflow/.local/lib/python3.7/site-packages/pandas/io/common.py", line 707, in get_handle
    newline="",
PermissionError: [Errno 13] Permission denied: '/opt/airflow/data/Churn.json'
[2024-10-30T00:23:17.034+0000] {taskinstance.py:1323} INFO - Marking task as FAILED. dag_id=bigdata, task_id=big_data, execution_date=20241030T002315, start_date=20241030T002316, end_date=20241030T002317
[2024-10-30T00:23:17.047+0000] {standard_task_runner.py:105} ERROR - Failed to execute job 139 for task big_data ([Errno 13] Permission denied: '/opt/airflow/data/Churn.json'; 6794)
[2024-10-30T00:23:17.070+0000] {local_task_job.py:208} INFO - Task exited with return code 1
[2024-10-30T00:23:17.091+0000] {taskinstance.py:2578} INFO - 0 downstream tasks scheduled from follow-on schedule check
