[2024-10-29T23:31:31.229+0000] {taskinstance.py:1083} INFO - Dependencies all met for <TaskInstance: windturbine.get_data manual__2024-10-29T23:31:28.776441+00:00 [queued]>
[2024-10-29T23:31:31.241+0000] {taskinstance.py:1083} INFO - Dependencies all met for <TaskInstance: windturbine.get_data manual__2024-10-29T23:31:28.776441+00:00 [queued]>
[2024-10-29T23:31:31.242+0000] {taskinstance.py:1279} INFO - 
--------------------------------------------------------------------------------
[2024-10-29T23:31:31.242+0000] {taskinstance.py:1280} INFO - Starting attempt 1 of 2
[2024-10-29T23:31:31.242+0000] {taskinstance.py:1281} INFO - 
--------------------------------------------------------------------------------
[2024-10-29T23:31:31.256+0000] {taskinstance.py:1300} INFO - Executing <Task(PythonOperator): get_data> on 2024-10-29 23:31:28.776441+00:00
[2024-10-29T23:31:31.262+0000] {standard_task_runner.py:55} INFO - Started process 1242 to run task
[2024-10-29T23:31:31.265+0000] {standard_task_runner.py:82} INFO - Running: ['***', 'tasks', 'run', 'windturbine', 'get_data', 'manual__2024-10-29T23:31:28.776441+00:00', '--job-id', '115', '--raw', '--subdir', 'DAGS_FOLDER/windturbine.py', '--cfg-path', '/tmp/tmpeohez9co']
[2024-10-29T23:31:31.267+0000] {standard_task_runner.py:83} INFO - Job 115: Subtask get_data
[2024-10-29T23:31:31.326+0000] {task_command.py:388} INFO - Running <TaskInstance: windturbine.get_data manual__2024-10-29T23:31:28.776441+00:00 [running]> on host 55e2175811f2
[2024-10-29T23:31:31.389+0000] {taskinstance.py:1509} INFO - Exporting the following env vars:
AIRFLOW_CTX_DAG_EMAIL=aws@evoluth.com.br
AIRFLOW_CTX_DAG_OWNER=***
AIRFLOW_CTX_DAG_ID=windturbine
AIRFLOW_CTX_TASK_ID=get_data
AIRFLOW_CTX_EXECUTION_DATE=2024-10-29T23:31:28.776441+00:00
AIRFLOW_CTX_TRY_NUMBER=1
AIRFLOW_CTX_DAG_RUN_ID=manual__2024-10-29T23:31:28.776441+00:00
[2024-10-29T23:31:31.454+0000] {taskinstance.py:1768} ERROR - Task failed with exception
Traceback (most recent call last):
  File "/home/airflow/.local/lib/python3.7/site-packages/airflow/operators/python.py", line 175, in execute
    return_value = self.execute_callable()
  File "/home/airflow/.local/lib/python3.7/site-packages/airflow/operators/python.py", line 192, in execute_callable
    return self.python_callable(*self.op_args, **self.op_kwargs)
  File "/opt/airflow/dags/windturbine.py", line 47, in process_file
    os.remove(Variable.get('path_file'))
PermissionError: [Errno 13] Permission denied: '/opt/airflow/data/data.json'
[2024-10-29T23:31:31.462+0000] {taskinstance.py:1323} INFO - Marking task as UP_FOR_RETRY. dag_id=windturbine, task_id=get_data, execution_date=20241029T233128, start_date=20241029T233131, end_date=20241029T233131
[2024-10-29T23:31:31.473+0000] {standard_task_runner.py:105} ERROR - Failed to execute job 115 for task get_data ([Errno 13] Permission denied: '/opt/airflow/data/data.json'; 1242)
[2024-10-29T23:31:31.517+0000] {local_task_job.py:208} INFO - Task exited with return code 1
[2024-10-29T23:31:31.548+0000] {taskinstance.py:2578} INFO - 0 downstream tasks scheduled from follow-on schedule check
