[2024-10-30T00:24:26.182+0000] {taskinstance.py:1083} INFO - Dependencies all met for <TaskInstance: pythonoperator.t1 manual__2024-10-30T00:24:24.508126+00:00 [queued]>
[2024-10-30T00:24:26.198+0000] {taskinstance.py:1083} INFO - Dependencies all met for <TaskInstance: pythonoperator.t1 manual__2024-10-30T00:24:24.508126+00:00 [queued]>
[2024-10-30T00:24:26.198+0000] {taskinstance.py:1279} INFO - 
--------------------------------------------------------------------------------
[2024-10-30T00:24:26.198+0000] {taskinstance.py:1280} INFO - Starting attempt 1 of 1
[2024-10-30T00:24:26.198+0000] {taskinstance.py:1281} INFO - 
--------------------------------------------------------------------------------
[2024-10-30T00:24:26.223+0000] {taskinstance.py:1300} INFO - Executing <Task(PythonOperator): t1> on 2024-10-30 00:24:24.508126+00:00
[2024-10-30T00:24:26.230+0000] {standard_task_runner.py:55} INFO - Started process 6923 to run task
[2024-10-30T00:24:26.234+0000] {standard_task_runner.py:82} INFO - Running: ['***', 'tasks', 'run', 'pythonoperator', 't1', 'manual__2024-10-30T00:24:24.508126+00:00', '--job-id', '142', '--raw', '--subdir', 'DAGS_FOLDER/pythonoperator.py', '--cfg-path', '/tmp/tmpjsw3_1hj']
[2024-10-30T00:24:26.237+0000] {standard_task_runner.py:83} INFO - Job 142: Subtask t1
[2024-10-30T00:24:26.323+0000] {task_command.py:388} INFO - Running <TaskInstance: pythonoperator.t1 manual__2024-10-30T00:24:24.508126+00:00 [running]> on host 55e2175811f2
[2024-10-30T00:24:26.431+0000] {taskinstance.py:1509} INFO - Exporting the following env vars:
AIRFLOW_CTX_DAG_OWNER=***
AIRFLOW_CTX_DAG_ID=pythonoperator
AIRFLOW_CTX_TASK_ID=t1
AIRFLOW_CTX_EXECUTION_DATE=2024-10-30T00:24:24.508126+00:00
AIRFLOW_CTX_TRY_NUMBER=1
AIRFLOW_CTX_DAG_RUN_ID=manual__2024-10-30T00:24:24.508126+00:00
[2024-10-30T00:24:26.445+0000] {taskinstance.py:1768} ERROR - Task failed with exception
Traceback (most recent call last):
  File "/home/airflow/.local/lib/python3.7/site-packages/airflow/operators/python.py", line 175, in execute
    return_value = self.execute_callable()
  File "/home/airflow/.local/lib/python3.7/site-packages/airflow/operators/python.py", line 192, in execute_callable
    return self.python_callable(*self.op_args, **self.op_kwargs)
  File "/opt/airflow/dags/pythonoperator.py", line 27, in data_cleaner
    dataset.to_csv("/opt/airflow/data/Churn_Clean.csv", sep=";", index=False)
  File "/home/airflow/.local/lib/python3.7/site-packages/pandas/core/generic.py", line 3482, in to_csv
    storage_options=storage_options,
  File "/home/airflow/.local/lib/python3.7/site-packages/pandas/io/formats/format.py", line 1105, in to_csv
    csv_formatter.save()
  File "/home/airflow/.local/lib/python3.7/site-packages/pandas/io/formats/csvs.py", line 243, in save
    storage_options=self.storage_options,
  File "/home/airflow/.local/lib/python3.7/site-packages/pandas/io/common.py", line 707, in get_handle
    newline="",
PermissionError: [Errno 13] Permission denied: '/opt/airflow/data/Churn_Clean.csv'
[2024-10-30T00:24:26.460+0000] {taskinstance.py:1323} INFO - Marking task as FAILED. dag_id=pythonoperator, task_id=t1, execution_date=20241030T002424, start_date=20241030T002426, end_date=20241030T002426
[2024-10-30T00:24:26.477+0000] {standard_task_runner.py:105} ERROR - Failed to execute job 142 for task t1 ([Errno 13] Permission denied: '/opt/airflow/data/Churn_Clean.csv'; 6923)
[2024-10-30T00:24:26.526+0000] {local_task_job.py:208} INFO - Task exited with return code 1
[2024-10-30T00:24:26.551+0000] {taskinstance.py:2578} INFO - 0 downstream tasks scheduled from follow-on schedule check
