[2024-10-30T00:16:42.643+0000] {taskinstance.py:1083} INFO - Dependencies all met for <TaskInstance: windturbine.get_data manual__2024-10-30T00:16:40.026114+00:00 [queued]>
[2024-10-30T00:16:42.668+0000] {taskinstance.py:1083} INFO - Dependencies all met for <TaskInstance: windturbine.get_data manual__2024-10-30T00:16:40.026114+00:00 [queued]>
[2024-10-30T00:16:42.669+0000] {taskinstance.py:1279} INFO - 
--------------------------------------------------------------------------------
[2024-10-30T00:16:42.669+0000] {taskinstance.py:1280} INFO - Starting attempt 1 of 2
[2024-10-30T00:16:42.669+0000] {taskinstance.py:1281} INFO - 
--------------------------------------------------------------------------------
[2024-10-30T00:16:42.689+0000] {taskinstance.py:1300} INFO - Executing <Task(PythonOperator): get_data> on 2024-10-30 00:16:40.026114+00:00
[2024-10-30T00:16:42.698+0000] {standard_task_runner.py:55} INFO - Started process 6072 to run task
[2024-10-30T00:16:42.702+0000] {standard_task_runner.py:82} INFO - Running: ['***', 'tasks', 'run', 'windturbine', 'get_data', 'manual__2024-10-30T00:16:40.026114+00:00', '--job-id', '125', '--raw', '--subdir', 'DAGS_FOLDER/windturbine.py', '--cfg-path', '/tmp/tmpnuld2ew4']
[2024-10-30T00:16:42.705+0000] {standard_task_runner.py:83} INFO - Job 125: Subtask get_data
[2024-10-30T00:16:42.793+0000] {task_command.py:388} INFO - Running <TaskInstance: windturbine.get_data manual__2024-10-30T00:16:40.026114+00:00 [running]> on host 55e2175811f2
[2024-10-30T00:16:42.872+0000] {taskinstance.py:1509} INFO - Exporting the following env vars:
AIRFLOW_CTX_DAG_EMAIL=aws@evoluth.com.br
AIRFLOW_CTX_DAG_OWNER=***
AIRFLOW_CTX_DAG_ID=windturbine
AIRFLOW_CTX_TASK_ID=get_data
AIRFLOW_CTX_EXECUTION_DATE=2024-10-30T00:16:40.026114+00:00
AIRFLOW_CTX_TRY_NUMBER=1
AIRFLOW_CTX_DAG_RUN_ID=manual__2024-10-30T00:16:40.026114+00:00
[2024-10-30T00:16:42.969+0000] {taskinstance.py:1768} ERROR - Task failed with exception
Traceback (most recent call last):
  File "/home/airflow/.local/lib/python3.7/site-packages/airflow/operators/python.py", line 175, in execute
    return_value = self.execute_callable()
  File "/home/airflow/.local/lib/python3.7/site-packages/airflow/operators/python.py", line 192, in execute_callable
    return self.python_callable(*self.op_args, **self.op_kwargs)
  File "/opt/airflow/dags/windturbine.py", line 47, in process_file
    os.remove(Variable.get('path_file'))
PermissionError: [Errno 13] Permission denied: '/opt/airflow/data/data.json'
[2024-10-30T00:16:42.983+0000] {taskinstance.py:1323} INFO - Marking task as UP_FOR_RETRY. dag_id=windturbine, task_id=get_data, execution_date=20241030T001640, start_date=20241030T001642, end_date=20241030T001642
[2024-10-30T00:16:42.999+0000] {standard_task_runner.py:105} ERROR - Failed to execute job 125 for task get_data ([Errno 13] Permission denied: '/opt/airflow/data/data.json'; 6072)
[2024-10-30T00:16:43.033+0000] {local_task_job.py:208} INFO - Task exited with return code 1
[2024-10-30T00:16:43.073+0000] {taskinstance.py:2578} INFO - 0 downstream tasks scheduled from follow-on schedule check
