[2024-10-29T23:29:39.217+0000] {taskinstance.py:1083} INFO - Dependencies all met for <TaskInstance: windturbine.get_data manual__2024-10-29T23:29:36.990914+00:00 [queued]>
[2024-10-29T23:29:39.231+0000] {taskinstance.py:1083} INFO - Dependencies all met for <TaskInstance: windturbine.get_data manual__2024-10-29T23:29:36.990914+00:00 [queued]>
[2024-10-29T23:29:39.231+0000] {taskinstance.py:1279} INFO - 
--------------------------------------------------------------------------------
[2024-10-29T23:29:39.231+0000] {taskinstance.py:1280} INFO - Starting attempt 1 of 2
[2024-10-29T23:29:39.231+0000] {taskinstance.py:1281} INFO - 
--------------------------------------------------------------------------------
[2024-10-29T23:29:39.246+0000] {taskinstance.py:1300} INFO - Executing <Task(PythonOperator): get_data> on 2024-10-29 23:29:36.990914+00:00
[2024-10-29T23:29:39.251+0000] {standard_task_runner.py:55} INFO - Started process 1023 to run task
[2024-10-29T23:29:39.255+0000] {standard_task_runner.py:82} INFO - Running: ['***', 'tasks', 'run', 'windturbine', 'get_data', 'manual__2024-10-29T23:29:36.990914+00:00', '--job-id', '109', '--raw', '--subdir', 'DAGS_FOLDER/windturbine.py', '--cfg-path', '/tmp/tmpqpw6qjhe']
[2024-10-29T23:29:39.256+0000] {standard_task_runner.py:83} INFO - Job 109: Subtask get_data
[2024-10-29T23:29:39.318+0000] {task_command.py:388} INFO - Running <TaskInstance: windturbine.get_data manual__2024-10-29T23:29:36.990914+00:00 [running]> on host 55e2175811f2
[2024-10-29T23:29:39.384+0000] {taskinstance.py:1509} INFO - Exporting the following env vars:
AIRFLOW_CTX_DAG_EMAIL=aws@evoluth.com.br
AIRFLOW_CTX_DAG_OWNER=***
AIRFLOW_CTX_DAG_ID=windturbine
AIRFLOW_CTX_TASK_ID=get_data
AIRFLOW_CTX_EXECUTION_DATE=2024-10-29T23:29:36.990914+00:00
AIRFLOW_CTX_TRY_NUMBER=1
AIRFLOW_CTX_DAG_RUN_ID=manual__2024-10-29T23:29:36.990914+00:00
[2024-10-29T23:29:39.450+0000] {taskinstance.py:1768} ERROR - Task failed with exception
Traceback (most recent call last):
  File "/home/airflow/.local/lib/python3.7/site-packages/airflow/operators/python.py", line 175, in execute
    return_value = self.execute_callable()
  File "/home/airflow/.local/lib/python3.7/site-packages/airflow/operators/python.py", line 192, in execute_callable
    return self.python_callable(*self.op_args, **self.op_kwargs)
  File "/opt/airflow/dags/windturbine.py", line 47, in process_file
    os.remove(Variable.get('path_file'))
PermissionError: [Errno 13] Permission denied: '/opt/airflow/data/data.json'
[2024-10-29T23:29:39.457+0000] {taskinstance.py:1323} INFO - Marking task as UP_FOR_RETRY. dag_id=windturbine, task_id=get_data, execution_date=20241029T232936, start_date=20241029T232939, end_date=20241029T232939
[2024-10-29T23:29:39.465+0000] {standard_task_runner.py:105} ERROR - Failed to execute job 109 for task get_data ([Errno 13] Permission denied: '/opt/airflow/data/data.json'; 1023)
[2024-10-29T23:29:39.506+0000] {local_task_job.py:208} INFO - Task exited with return code 1
[2024-10-29T23:29:39.534+0000] {taskinstance.py:2578} INFO - 0 downstream tasks scheduled from follow-on schedule check
