[2024-10-29T23:10:13.394+0000] {taskinstance.py:1083} INFO - Dependencies all met for <TaskInstance: hook.create_table_task manual__2024-10-29T23:10:12.496634+00:00 [queued]>
[2024-10-29T23:10:13.407+0000] {taskinstance.py:1083} INFO - Dependencies all met for <TaskInstance: hook.create_table_task manual__2024-10-29T23:10:12.496634+00:00 [queued]>
[2024-10-29T23:10:13.407+0000] {taskinstance.py:1279} INFO - 
--------------------------------------------------------------------------------
[2024-10-29T23:10:13.407+0000] {taskinstance.py:1280} INFO - Starting attempt 1 of 1
[2024-10-29T23:10:13.407+0000] {taskinstance.py:1281} INFO - 
--------------------------------------------------------------------------------
[2024-10-29T23:10:13.422+0000] {taskinstance.py:1300} INFO - Executing <Task(PythonOperator): create_table_task> on 2024-10-29 23:10:12.496634+00:00
[2024-10-29T23:10:13.427+0000] {standard_task_runner.py:55} INFO - Started process 1078 to run task
[2024-10-29T23:10:13.433+0000] {standard_task_runner.py:82} INFO - Running: ['***', 'tasks', 'run', 'hook', 'create_table_task', 'manual__2024-10-29T23:10:12.496634+00:00', '--job-id', '77', '--raw', '--subdir', 'DAGS_FOLDER/hooks.py', '--cfg-path', '/tmp/tmppp3t9qek']
[2024-10-29T23:10:13.433+0000] {standard_task_runner.py:83} INFO - Job 77: Subtask create_table_task
[2024-10-29T23:10:13.534+0000] {task_command.py:388} INFO - Running <TaskInstance: hook.create_table_task manual__2024-10-29T23:10:12.496634+00:00 [running]> on host 55e2175811f2
[2024-10-29T23:10:13.626+0000] {taskinstance.py:1509} INFO - Exporting the following env vars:
AIRFLOW_CTX_DAG_OWNER=***
AIRFLOW_CTX_DAG_ID=hook
AIRFLOW_CTX_TASK_ID=create_table_task
AIRFLOW_CTX_EXECUTION_DATE=2024-10-29T23:10:12.496634+00:00
AIRFLOW_CTX_TRY_NUMBER=1
AIRFLOW_CTX_DAG_RUN_ID=manual__2024-10-29T23:10:12.496634+00:00
[2024-10-29T23:10:13.638+0000] {base.py:73} INFO - Using connection ID 'postgres' for task execution.
[2024-10-29T23:10:13.642+0000] {taskinstance.py:1768} ERROR - Task failed with exception
Traceback (most recent call last):
  File "/home/airflow/.local/lib/python3.7/site-packages/airflow/operators/python.py", line 175, in execute
    return_value = self.execute_callable()
  File "/home/airflow/.local/lib/python3.7/site-packages/airflow/operators/python.py", line 192, in execute_callable
    return self.python_callable(*self.op_args, **self.op_kwargs)
  File "/opt/airflow/dags/hooks.py", line 14, in create_table
    pg_hook.run('create table if not exists teste2(id int);', autocommit=True)
  File "/home/airflow/.local/lib/python3.7/site-packages/airflow/providers/common/sql/hooks/sql.py", line 342, in run
    with closing(self.get_conn()) as conn:
  File "/home/airflow/.local/lib/python3.7/site-packages/airflow/providers/postgres/hooks/postgres.py", line 144, in get_conn
    self.conn = psycopg2.connect(**conn_args)
  File "/home/airflow/.local/lib/python3.7/site-packages/psycopg2/__init__.py", line 122, in connect
    conn = _connect(dsn, connection_factory=connection_factory, **kwasync)
psycopg2.OperationalError: connection to server at "postgres" (172.20.0.3), port 5432 failed: fe_sendauth: no password supplied

[2024-10-29T23:10:13.656+0000] {taskinstance.py:1323} INFO - Marking task as FAILED. dag_id=hook, task_id=create_table_task, execution_date=20241029T231012, start_date=20241029T231013, end_date=20241029T231013
[2024-10-29T23:10:13.676+0000] {standard_task_runner.py:105} ERROR - Failed to execute job 77 for task create_table_task (connection to server at "postgres" (172.20.0.3), port 5432 failed: fe_sendauth: no password supplied
; 1078)
[2024-10-29T23:10:13.722+0000] {local_task_job.py:208} INFO - Task exited with return code 1
[2024-10-29T23:10:13.773+0000] {taskinstance.py:2578} INFO - 0 downstream tasks scheduled from follow-on schedule check
